# 代码输出

```typescript
const promise = new Promise((resolve, reject) => {
  console.log(1);
  console.log(2);
});
promise.then(() => {
  console.log(3);
});
console.log(4);
```

输出结果：1、2、4；`Promise`当中的`executor`函数是立即执行函数，也是一个同步函数，所以`1 2`会被输出，然后执行同步代码`4`，由于`promise`没有调用`resolve`则该`promise`的状态一直是`pending`，也就导致`then`语句没有输出



```typescript
const promise1 = new Promise((resolve, reject) => {
  console.log('promise1')
  resolve('resolve1')
})
const promise2 = promise1.then(res => {
  console.log(res)
})
console.log('1', promise1);
console.log('2', promise2);
```

输出结果：`promise1 -> 1 fulfilled -> 2 pending -> resolve1`；`Promise`的`executor`会立即执行，输出`promise1`然后调用`resolve`创建一个微任务，然后输出同步代码`1 resolved / 2 pending`，`promise2`的状态还没有被改变所以就是等待状态，然后就执行微任务输出`resolve1`



```typescript
const promise = new Promise((resolve, reject) => {
  console.log(1);
  setTimeout(() => {
    console.log("timerStart");
    resolve("success");
    console.log("timerEnd");
  }, 0);
  console.log(2);
});
promise.then((res) => {
  console.log(res);
});
console.log(4);
```

输出结果：`1 -> 2 -> 4 -> timerStart -> timerEnd -> success`；先执行`executor`的同步代码输出`1 2`，遇到`setTimeout`加入宏任务队列，遇到`promise.then`但`promise`的状态是`pending`所以不会被执行，然后输出`4`；没有微任务在队列当中，所以就执行宏任务`setTimeout`，输出`timerStart`，遇到`resolve`加入微任务队列，继续输出`timerEnd`，然后执行微任务输出`success`



```typescript
Promise.resolve().then(() => {
  console.log('promise1');
  const timer2 = setTimeout(() => {
    console.log('timer2')
  }, 0)
});
const timer1 = setTimeout(() => {
  console.log('timer1')
  Promise.resolve().then(() => {
    console.log('promise2')
  })
}, 0)
console.log('start');
```

输出结果：`start -> promise1 -> timer1 ->  promise2 -> timer2`；`Promise.resolve`是微任务，加入微任务队列，`timer1`是宏任务加入宏任务队列，执行同步代码`start`，然后去执行微任务队列，输出`promise1`，遇见`timer2`加入宏任务队列，微任务执行完了去执行宏任务`timer1`，输出`time1`，遇见微任务`Promise.resolve`执行微任务输出`promise2`；微任务队列也清空，去执行宏任务`timer2`，输出`timer2`



```typescript
const promise = new Promise((resolve, reject) => {
    resolve('success1');
    reject('error');
    resolve('success2');
});
promise.then((res) => {
    console.log('then:', res);
}).catch((err) => {
    console.log('catch:', err);
})
```

输出结果：`then success1`，由于`Promise`状态凝固的特性，只要状态从`pending -> fullfilled / rejected`的时候就不会被再次改变，也就是说后续执行的`resolve / reject`都是无效的。


```typescript
Promise.resolve(1)
  .then(2)
  .then(Promise.resolve(3))
  .then(console.log)
```

输出结果：`1`，当`then`方法接收的参数不是一个函数的时候，会解释为`then(null)`，从而导致`Promise`的结果会继续传到下一个`then`当中去。传入非函数则会发生**值透传**。



```typescript
const promise1 = new Promise((resolve, reject) => {
  setTimeout(() => {
    resolve('success')
  }, 1000)
})
const promise2 = promise1.then(() => {
  throw new Error('error!!!')
})
console.log('promise1', promise1)
console.log('promise2', promise2)
setTimeout(() => {
  console.log('promise1', promise1)
  console.log('promise2', promise2)
}, 2000)
```

输出结果：`promise1 pending -> promise2 pending -> error -> promise1 fulfilled -> promise2 rejected `；执行遇到`promise1`并且执行`executor`函数，函数内部存在`setTimeout`，将延时器加入宏任务队列，遇到`promise1.then`加入微任务队列，输出同步代码`promise1 pending / promise2 pending`，因为此时两个`promise`的状态都没有修改；然后执行宏任务`setTimeout 1000`，内部调用了`resolve`，将`resolve`加入微任务队列，然后去执行微任务队列，输出`error`，最后才去执行最后一个延时器宏任务，此时`promise1 fulfilled / promise2 rejected`，在`promise`当中抛出异常都会修改`promise`的状态为`rejected`



```typescript
Promise.resolve().then(() => {
  return new Error('error!!!')
}).then(res => {
  console.log("then: ", res)
}).catch(err => {
  console.log("catch: ", err)
})
```

输出结果：`then: error!!!`，由于这里没有通过`throw`来抛出错误，如果通过`throw`那么就会走`catch`回调，而是`new Error`然后返回，任何一个非`promise`的值返回的时候都会被包裹成一个`promise`，也就是会`Promise.resolve(new Error(error))`，所以也就会导致后面被`then`捕获



```typescript
Promise.reject('err!!!')
  .then((res) => {
    console.log('success', res)
  }, (err) => {
    console.log('error', err)
  }).catch(err => {
    console.log('catch', err)
  })
```

输出结果：`error err!!!`；由于执行了`reject`，`promise`的状态变成`rejected`，所以就执行了`then`方法的第二个函数，因为已经被捕获了，所以后续的`catch`不会执行；**同理如果不传入第二个函数，那么这个错误就会被`catch`捕获然后输出`catch err!!!`**

```typescript
Promise.resolve()
  .then(function success (res) {
    throw new Error('error!!!')
  }, function fail1 (err) {
    console.log('fail1', err)
  }).catch(function fail2 (err) {
    console.log('fail2', err)
  })
```

这段代码也是类似，由于在`then`函数中抛出错误，`then`方法的两个函数只能执行一个，所以该错误就会被`catch`接收处理，输出`fail2 error!!!`



```typescript
Promise.resolve('1')
  .then(res => {
    console.log(res)
  })
  .finally(() => {
    console.log('finally')
  })
Promise.resolve('2')
  .finally(() => {
    console.log('finally2')
    return '我是finally2返回的值'
  })
  .then(res => {
    console.log('finally2后面的then函数', res)
  })
```

输出结果：`1 -> finally2 -> finally -> finally2后面的then函数 2`；`finally`方法不管是`promise`的状态是成功还是失败都会被执行，它返回的默认是上一次`promise`的返回值；第一个`promise`执行完毕后会执行`then`方法，然后将`finally`放入微任务队列，第二个`promise`执行完毕后会执行`finally`，将`then`方法放入微任务队列，然后再去清空微任务队列



```typescript
async function async1() {
  console.log("async1 start");
  await async2();
  console.log("async1 end");
}
async function async2() {
  console.log("async2");
}
async1();
console.log('start')
```

输出结果：`async1 start -> async2 -> start -> async1 end`；代码执行到`async1()`进入函数内部，执行同步代码`async1 start`，然后又遇到第二个函数`async2`，进入执行`async2`，退出，由于`await`修饰了`async2`，`await`阻塞了后面代码的执行，先跳出`async1`函数，执行完`start`后再去执行`async1 end`



```typescript
async function async1() {
  console.log("async1 start");   // 1
  await async2();
  console.log("async1 end");  // 4
  setTimeout(() => {
    console.log('timer1')  // 7
  }, 0)
}
async function async2() {
  setTimeout(() => {
    console.log('timer2')  // 5
  }, 0)
  console.log("async2");  // 2
}
async1();
setTimeout(() => {
  console.log('timer3')  // 6
}, 0)
console.log("start")  // 3
```

输出结果：`async1 start -> async2 -> start -> async1 end -> timer2 -> timer3 -> timer1`；先执行到`async1()`，到`async1`函数内部执行同步代码，`async1 start`，遇到了`await async2`，执行`async2`的同步代码输出`async2`，并且将`timer2`放入宏任务队列，然后跳出`async1`函数，向下执行遇到`timer3`放入宏任务队列，执行同步代码`start`，然后执行微任务`await async2`后面的代码，输出`async1 end`，将`timer1`加入宏任务队列；最后清空宏任务队列：`timer2 - timer3 - timer1`



```typescript
async function async1 () {
  console.log('async1 start');
  await new Promise(resolve => {
    console.log('promise1')
  })
  console.log('async1 success');
  return 'async1 end'
}
console.log('srcipt start')
async1().then(res => console.log(res))
console.log('srcipt end')
```

输出结果：`script start -> async1 start -> promise1 -> script end`；先执行同步代码`script start`，然后进入`async1`函数，执行同步代码`async1 start`，遇到`await`的`promise`，执行`promise`的`executor`函数输出`promise1`，这里的`await`的`promise`并没有执行`resolve`修改`promise`的状态，所以后续的代码是不会被执行，跳出`async1`函数，执行`script end`；同理`async1().then`方法后面由于`await`当中的代码阻塞，无法执行`return async1 end`也就导致了`then`函数不执行