# 异步事件循环面试题

```javascript
async function async1() {
  console.log("async1 start");  // 2
  await async2();
  console.log("async1 end");  // 6
}

async function async2() {
  console.log("async2");  // 3
}

console.log("script start");  // 1

setTimeout(function() {
  console.log("setTimeout");  // 8
}, 0);

async1();

new Promise(resolve => {
  console.log("promise1");  // 4
  resolve();
}).then(function() {
  console.log("promise2");  // 7
});
console.log('script end')  // 5
```

输出结果：`script start -> async1 start -> async2 -> promise1 -> script end -> async1 end -> promise2 -> setTimeout`

* 从上向下执行，先输出`script start`，然后遇到`setTimeout`，加入宏任务队列
* 调用`async1()`，进入函数内部输出`async1 start`，然后`await async2()`进入`async2`函数内部，输出`async2`；然后`await`阻塞后面的代码，先跳出`async1`方法
*  执行到`Promise`的`executor`，属于同步代码，输出`promise1`，然后遇到`resolve`微任务，加入微任务队列，次数微任务队列有两个，一个是`async1`后续的代码，一个是`then`的代码
* 然后执行同步代码输出`script end`
* 同步代码都指向完毕，需要去清空微任务队列，先输出`async1 end`，然后再去执行`then`，输出`promise2`
* 最后微任务队列清空了，才去执行`setTimeout`的内容



```javascript
const first = () => (new Promise((resolve, reject) => {
    console.log(3);  // 1
    let p = new Promise((resolve, reject) => {
        console.log(7);  // 2
        setTimeout(() => {
            console.log(5);  // 6
            resolve(6);
            console.log(p)  // 7
        }, 0)
        resolve(1);  // 内层promise
    });
    resolve(2);  // 外层promise
    p.then((arg) => {
        console.log(arg);  // 4
    });
}));
first().then((arg) => {
    console.log(arg);  // 5
});
console.log(4);  // 3
```

输出结果：`3 -> 7 -> 4 -> 1 -> 2 -> 5 -> fulfilled`

* 先是执行了`first()`方法进入函数内部，输出同步代码`3`
* 然后函数内部又定义了一个`Promise`，先执行`executor`函数，输出`7`，然后遇到`setTimeout`加入宏任务队列，遇到`resolve(1)`加入微任务队列
* 然后执行`executor`后去执行到`resolve(7)`，再次加入微任务队列
* 然后执行同步代码输出`4`
* 同步代码执行完毕后，清空微任务队列，此时微任务队列存在：`resolve(1) -> resolve(2)`，所以就输出`1 -> 2`
* 微任务队列清空，执行宏任务，输出同步代码`5`，然后遇到`resolve(6)`，由于`p`的状态早在上一轮微任务当中修改为`fulfilled`，状态凝固，所以这里再次调用`resolve`是无效的，最后就是输出`p -> fulfilled`



```javascript
const async1 = async () => {
  console.log('async1');  // 2
  setTimeout(() => {
    console.log('timer1')  // 7
  }, 2000)
  await new Promise(resolve => {
    console.log('promise1')  // 3
  })
  console.log('async1 end')
  return 'async1 success'
} 
console.log('script start');  // 1
async1().then(res => console.log(res));
console.log('script end');  // 4
Promise.resolve(1)
  .then(2)
  .then(Promise.resolve(3))
  .catch(4)
  .then(res => console.log(res))  // 5
setTimeout(() => {
  console.log('timer2')  // 6
}, 1000)
```

输出结果：`script start -> async1 -> promise1 -> script end -> 1 -> timer2 -> timer1`

* 执行同步代码输出`script start`
* 然后调用了`async1`函数，进入`async1`函数内部，执行同步代码输出`async1`，遇到`setTimeout`加入宏任务队列，然后遇到`await`，执行`Promise`当中的`executor`函数，输出`promise1`，跳出`async1`函数
* 执行同步代码输出`script end`
* 将`Promise.resolve`放入微任务队列
* 将`setTimeout`放入宏任务队列
* 同步代码执行完毕，情况微任务队列，这里`resolve(1)`，只要`then`方法传入的不是一个函数，那么`resolve`的值就会发生值透传，会一直传递到`then`的参数为函数上，也就是最后一个`then`，输出`1`
* 最后就是依次执行两个延时器输出`timer2 -> timer1`



```javascript
const p1 = new Promise((resolve) => {
  setTimeout(() => {
    resolve('resolve3');
    console.log('timer1')
  }, 0)
  resolve('resovle1');
  resolve('resolve2');
}).then(res => {
  console.log(res)  // resolve1
  setTimeout(() => {
    console.log(p1)
  }, 1000) 
}).finally(res => {  // finally不接受任何参数
  console.log('finally', res)
})
```

输出结果：`resolve1 -> undefined -> timer1 -> fulfilled`

* 执行`Promise`的`executor`函数，遇到`setTimeout`加入宏任务队列；
* 然后执行`resolve('resolve1') / resolve('resolve2')`；依次放入微任务队列
* 同步代码执行完毕，清空微任务队列，先执行`resolve('resolve1')`，此时`p1`的状态变为`fulfilled`，后续其他的`resolve / reject`操作都是无效的
* 然后**输出`then`当中的`resolve1`**，将`setTimeout`放入宏任务队列，然后再执行`finally`当中的代码，`finally`函数的参数是`then`的返回值，由于`then`并没有`return`，则这里**输出`finally undefine`**
* 执行宏任务，由于`p1`状态已经凝固，所以`resolve`无效，**输出`timer1`**
* 第二个延时器输出`Promise(<fulfilled>: undefined)`；`undefined`的原因是在`then`函数中并没有返回值



```javascript
console.log('1');

setTimeout(function() {
    console.log('2');
    process.nextTick(function() {
        console.log('3');
    })
    new Promise(function(resolve) {
        console.log('4');
        resolve();
    }).then(function() {
        console.log('5')
    })
})
process.nextTick(function() {
    console.log('6');
})
new Promise(function(resolve) {
    console.log('7');
    resolve();
}).then(function() {
    console.log('8')
})

setTimeout(function() {
    console.log('9');
    process.nextTick(function() {
        console.log('10');
    })
    new Promise(function(resolve) {
        console.log('11');
        resolve();
    }).then(function() {
        console.log('12')
    })
})
```

输出结果：`1 -> 7 -> 6 -> 8 -> 2 -> 4 -> 3 -> 5 -> 9 -> 11 -> 10 -> 12`；**`process.nextTick`回调函数属于微任务**

* 执行同步代码**输出`1`**；
* 将`setTimeout`放入宏任务队列等待执行；将`process.nextTick`放入微任务队列等待执行
* 执行`Promise`的`executor`函数，**输出`7`**，然后执行了`resolve`方法，将`then`函数放入微任务队列
* 执行底部的`setTimeout`放入宏任务队列
* 此时同步代码全部执行完毕，去清空微任务队列，此时微任务队列：`process.nextTick - then`；**输出`6 -> 8`**，微任务队列清空
* 执行宏任务队列代码，取出第一个宏任务`setTimeout`，执行其中的同步代码，**输出`2`**，然后遇到`process.nextTick`放入微任务，再执行`Promise.executor`的代码，**输出`4`**，再将`resolve`放入微任务队列，当前的宏任务已经执行完毕，去清空微任务
* 输出`3 -> 5`，清空微任务
* 第二个宏任务和上一个宏任务执行类似。



```typescript
console.log(1)

setTimeout(() => {
  console.log(2)
})

new Promise(resolve =>  {
  console.log(3)
  resolve(4)
}).then(d => console.log(d))

setTimeout(() => {
  console.log(5)
  new Promise(resolve =>  {
    resolve(6)
  }).then(d => console.log(d))
})

setTimeout(() => {
  console.log(7)
})

console.log(8)
```

输出结果：`1 -> 3 -> 8 -> 4 -> 2 -> 5 -> 6 -> 7`；

* 执行同步代码输出`1`
* 将`setTimeout`加入宏任务队列
* 执行`Promise`的`executor`函数，输出`3`，将`resolve(4)`放入微任务队列
* 将后续的两个`setTimeout`加入宏任务队列，此时宏任务队列存在三个`setTimeout`
* 执行同步代码输出`8`
* 同步代码执行完毕，执行微任务输出`4`
* 微任务队列清空，执行第一个宏任务输出`2`；此时微任务队列仍然没有任务，继续执行宏任务
* 执行第二个宏任务，输出`5`，将`resolve(6)`放入微任务队列，宏任务执行完毕，清空微任务队列，输出`6`
* 最后执行最后一个宏任务输出`7`



```javascript
console.log(1);
    
setTimeout(() => {
  console.log(2);
  Promise.resolve().then(() => {
    console.log(3)
  });
});

new Promise((resolve, reject) => {
  console.log(4)
  resolve(5)
}).then((data) => {
  console.log(data);
})

setTimeout(() => {
  console.log(6);
})

console.log(7);
```

输出结果：`1 -> 4 -> 7 -> 5 -> 2 -> 3 -> 6`



```javascript
Promise.resolve().then(() => {
  console.log('1');
  throw 'Error';
}).then(() => {
  console.log('2');
}).catch(() => {
  console.log('3');
  throw 'Error';
}).then(() => {
  console.log('4');
}).catch(() => {
  console.log('5');
}).then(() => {
  console.log('6');
});
```

输出结果：`1 -> 3 -> 5 -> 6`

* 在第一个`then`函数当中通过`throw`抛出错误，该错误会被后续的第一个`catch`捕获
* `catch`捕获后输出`3`，继续抛出错误
* 第三个`catch`捕获到上一次的错误之后，输出`5`，在该`catch`没有抛出错误，则后续的`then`都会被执行



```javascript
setTimeout(function () {
  console.log(1);
}, 100);

new Promise(function (resolve) {
  console.log(2);
  resolve();
  console.log(3);
}).then(function () {
  console.log(4);
  new Promise((resove, reject) => {
    console.log(5);
    setTimeout(() =>  {
      console.log(6);
    }, 10);
  })
});
console.log(7);
console.log(8);
```

输出结果：`2 -> 3 -> 7 -> 8 -> 4 -> 5 -> 6 -> 1`

* 将`setTimeout`加入宏任务队列
* 执行`Promise`的`executor`输出`2 -> 3`，然后将`resolve`放入微任务队列
* 执行最后的两个同步代码：`7 -> 8`
* 同步代码执行完毕，清空微任务队列
* 执行`resolve`微任务，输出`4 -> 5`，然后将`setTimeout`加入宏任务队列
* 清空宏任务队列输出：`6 -> 1`



```javascript
Promise.resolve(1)
  .then(res => {
    console.log(res);
    return 2;
  })
  .catch(err => {
    return 3;
  })
  .then(res => {
    console.log(res);
  });
```

输出：`1 3`；`then`方法内部`return 2`，默认会进行包装，也就是转为`resolve(2)`，会被下一个`then`函数捕获



```javascript
Promise.resolve('1')  
.finally(() => {
    console.log('finally1')
    throw new Error('我是finally中抛出的异常')
  })
  .then(res => {
    console.log('finally后面的then函数', res)
  })
  .catch(err => {
    console.log('捕获错误', err)
  })
```

输出：`finally1 捕获错误 我是finally中抛出的异常`；`finally`中`throw`的异常可以被后面的`catch`捕获



```javascript
function runAsync (x) {
    const p = new Promise(r => setTimeout(() => r(x, console.log(x)), 1000))
    return p
}

Promise.all([runAsync(1), runAsync(2), runAsync(3)]).then(res => console.log(res))
```

输出：`1 2 3 [1,2,3]`；`Promise.all`函数的`then`函数内的`res`返回值是`promise`数组执行的结果，按顺序放入结果数组当中



```javascript
async function async1 () {
  console.log('async1 start');
  await new Promise(resolve => {
    console.log('promise1')
    resolve('promise1 resolve')
  }).then(res => console.log(res))
  console.log('async1 success');
  return 'async1 end'
}
console.log('srcipt start')
async1().then(res => console.log(res))
console.log('srcipt end')
```

输出：`script start -> async1 start -> promise1 -> script end -> promise1 resolve -> async1 success -> async1 end`；
`await`会堵塞后续代码的执行，当`promise`的状态为`resolved`的时候，才可以开始执行后续的代码



```javascript
async function async1 () {
  await async2();
  // 以下代码不会被执行
  console.log('async1');
  return 'async1 success'
}
async function async2 () {
  return new Promise((resolve, reject) => {
    console.log('async2')
    reject('error')
  })
}
// async1的状态一直是pending
async1().then(res => console.log(res))
```

输出：`async2 error`；如果在`async`函数中抛出错误，例如在`async2`函数的`promise`执行了`reject`，则`await async2`后续的代码不会被执行


```javascript
const async1 = async () => {
  console.log('async1');
  setTimeout(() => {
    console.log('timer1')
  }, 2000)
  await new Promise(resolve => {
    console.log('promise1')
  })
  console.log('async1 end')
  return 'async1 success'
} 
console.log('script start');
async1().then(res => console.log(res));
console.log('script end');
Promise.resolve(1)
  .then(2)
  .then(Promise.resolve(3))
  .catch(4)
  .then(res => console.log(res))
setTimeout(() => {
  console.log('timer2')
}, 1000)
```

输出：`script start -> async1 -> promise1 -> script end -> 1 -> timer2 -> timer1`
在`async1`中，`await promise`会堵塞后续代码的执行，并且`promise`的状态一直是`pending`，所以后面的代码不会被执行




```javascript
const p1 = new Promise((resolve) => {
  setTimeout(() => {
    resolve('resolve3');
    console.log('timer1')
  }, 0)
  resolve('resovle1');
  resolve('resolve2');
}).then(res => {
  console.log(res)  // resolve1
  setTimeout(() => {
    console.log(p1)
  }, 1000)
}).finally(res => {
  console.log('finally', res)
})
```

输出：`resolve1 -> finally undefined -> timer1 -> fulfilled`
最先执行的是`resolve('resolve1')`，将`p1`的状态修改为`fulfilled`；由于`then`函数内部没有`return`值，那么`finally`函数接收的是`undefined`，如果在`then`函数内部`return`值，那么`finally`可以接收到